Exception in thread Thread-61 (run):
Traceback (most recent call last):
  File "/mnt/main/CodeSpace/Project/SocialMediaStreamDownloader/venv/lib/python3.12/site-packages/urllib3/connectionpool.py", line 534, in _make_request
    response = conn.getresponse()
               ^^^^^^^^^^^^^^^^^^
  File "/mnt/main/CodeSpace/Project/SocialMediaStreamDownloader/venv/lib/python3.12/site-packages/urllib3/connection.py", line 516, in getresponse
    httplib_response = super().getresponse()
                       ^^^^^^^^^^^^^^^^^^^^^
  File "/usr/local/python312/lib/python3.12/http/client.py", line 1428, in getresponse
    response.begin()
  File "/usr/local/python312/lib/python3.12/http/client.py", line 331, in begin
    version, status, reason = self._read_status()
                              ^^^^^^^^^^^^^^^^^^^
  File "/usr/local/python312/lib/python3.12/http/client.py", line 292, in _read_status
    line = str(self.fp.readline(_MAXLINE + 1), "iso-8859-1")
               ^^^^^^^^^^^^^^^^^^^^^^^^^^^^^^
  File "/usr/local/python312/lib/python3.12/socket.py", line 720, in readinto
    return self._sock.recv_into(b)
           ^^^^^^^^^^^^^^^^^^^^^^^
  File "/usr/local/python312/lib/python3.12/ssl.py", line 1251, in recv_into
    return self.read(nbytes, buffer)
           ^^^^^^^^^^^^^^^^^^^^^^^^^
  File "/usr/local/python312/lib/python3.12/ssl.py", line 1103, in read
    return self._sslobj.read(len, buffer)
           ^^^^^^^^^^^^^^^^^^^^^^^^^^^^^^
TimeoutError: The read operation timed out

The above exception was the direct cause of the following exception:

Traceback (most recent call last):
  File "/mnt/main/CodeSpace/Project/SocialMediaStreamDownloader/venv/lib/python3.12/site-packages/requests/adapters.py", line 667, in send
    resp = conn.urlopen(
           ^^^^^^^^^^^^^
  File "/mnt/main/CodeSpace/Project/SocialMediaStreamDownloader/venv/lib/python3.12/site-packages/urllib3/connectionpool.py", line 841, in urlopen
    retries = retries.increment(
              ^^^^^^^^^^^^^^^^^^
  File "/mnt/main/CodeSpace/Project/SocialMediaStreamDownloader/venv/lib/python3.12/site-packages/urllib3/util/retry.py", line 474, in increment
    raise reraise(type(error), error, _stacktrace)
          ^^^^^^^^^^^^^^^^^^^^^^^^^^^^^^^^^^^^^^^^
  File "/mnt/main/CodeSpace/Project/SocialMediaStreamDownloader/venv/lib/python3.12/site-packages/urllib3/util/util.py", line 39, in reraise
    raise value
  File "/mnt/main/CodeSpace/Project/SocialMediaStreamDownloader/venv/lib/python3.12/site-packages/urllib3/connectionpool.py", line 787, in urlopen
    response = self._make_request(
               ^^^^^^^^^^^^^^^^^^^
  File "/mnt/main/CodeSpace/Project/SocialMediaStreamDownloader/venv/lib/python3.12/site-packages/urllib3/connectionpool.py", line 536, in _make_request
    self._raise_timeout(err=e, url=url, timeout_value=read_timeout)
  File "/mnt/main/CodeSpace/Project/SocialMediaStreamDownloader/venv/lib/python3.12/site-packages/urllib3/connectionpool.py", line 367, in _raise_timeout
    raise ReadTimeoutError(
urllib3.exceptions.ReadTimeoutError: HTTPSConnectionPool(host='webcast.amemv.com', port=443): Read timed out. (read timeout=10)

During handling of the above exception, another exception occurred:

Traceback (most recent call last):
  File "/mnt/main/CodeSpace/Project/SocialMediaStreamDownloader/./backend/src/platform/douyin/douyin_live_downloader.py", line 228, in run
    response = self.query_url(
               ^^^^^^^^^^^^^^^
  File "/mnt/main/CodeSpace/Project/SocialMediaStreamDownloader/./backend/src/platform/douyin/douyin_live_downloader.py", line 557, in query_url
    return request(method=method, url=url, params=params, timeout=timeout, headers=headers)
           ^^^^^^^^^^^^^^^^^^^^^^^^^^^^^^^^^^^^^^^^^^^^^^^^^^^^^^^^^^^^^^^^^^^^^^^^^^^^^^^^
  File "/mnt/main/CodeSpace/Project/SocialMediaStreamDownloader/venv/lib/python3.12/site-packages/requests/api.py", line 59, in request
    return session.request(method=method, url=url, **kwargs)
           ^^^^^^^^^^^^^^^^^^^^^^^^^^^^^^^^^^^^^^^^^^^^^^^^^
  File "/mnt/main/CodeSpace/Project/SocialMediaStreamDownloader/venv/lib/python3.12/site-packages/requests/sessions.py", line 589, in request
    resp = self.send(prep, **send_kwargs)
           ^^^^^^^^^^^^^^^^^^^^^^^^^^^^^^
  File "/mnt/main/CodeSpace/Project/SocialMediaStreamDownloader/venv/lib/python3.12/site-packages/requests/sessions.py", line 724, in send
    history = [resp for resp in gen]
                                ^^^
  File "/mnt/main/CodeSpace/Project/SocialMediaStreamDownloader/venv/lib/python3.12/site-packages/requests/sessions.py", line 265, in resolve_redirects
    resp = self.send(
           ^^^^^^^^^^
  File "/mnt/main/CodeSpace/Project/SocialMediaStreamDownloader/venv/lib/python3.12/site-packages/requests/sessions.py", line 703, in send
    r = adapter.send(request, **kwargs)
        ^^^^^^^^^^^^^^^^^^^^^^^^^^^^^^^
  File "/mnt/main/CodeSpace/Project/SocialMediaStreamDownloader/venv/lib/python3.12/site-packages/requests/adapters.py", line 713, in send
    raise ReadTimeout(e, request=request)
requests.exceptions.ReadTimeout: HTTPSConnectionPool(host='webcast.amemv.com', port=443): Read timed out. (read timeout=10)

During handling of the above exception, another exception occurred:

Traceback (most recent call last):
  File "/usr/local/python312/lib/python3.12/threading.py", line 1075, in _bootstrap_inner
    self.run()
  File "/usr/local/python312/lib/python3.12/threading.py", line 1012, in run
    self._target(*self._args, **self._kwargs)
  File "/mnt/main/CodeSpace/Project/SocialMediaStreamDownloader/./backend/src/platform/douyin/douyin_live_downloader.py", line 241, in run
    print("ERROR: Query share url failed! \tstatus:{} \tERROR:{}".format(response.status_code, e))
                                                                         ^^^^^^^^
UnboundLocalError: cannot access local variable 'response' where it is not associated with a value
